{
  "comments": [
    {
      "key": {
        "uuid": "7eedce01_72b5aecf",
        "filename": "third_party/WebKit/Tools/Scripts/webkitpy/w3c/test_exporter.py",
        "patchSetId": 1
      },
      "lineNbr": 37,
      "author": {
        "id": 1003190
      },
      "writtenOn": "2017-08-15T18:13:37Z",
      "side": 1,
      "message": "Nit: This could also return an exit code, or alternately return \"True for success, False for failure\".",
      "revId": "c160252a40f1ab761bd54169ebad363f61a9ed52",
      "serverId": "3ce6091f-6c88-37e8-8c75-72f92ae8dfba",
      "unresolved": true
    },
    {
      "key": {
        "uuid": "56c05f35_89564ab9",
        "filename": "third_party/WebKit/Tools/Scripts/webkitpy/w3c/test_exporter.py",
        "patchSetId": 1
      },
      "lineNbr": 37,
      "author": {
        "id": 1168241
      },
      "writtenOn": "2017-08-16T19:18:43Z",
      "side": 1,
      "message": "Done - reversed to be the way you described. I also added an assert on the return value of TestExporter.run to all of its unit tests, and added a new unit test to test the case when there are errors.",
      "parentUuid": "7eedce01_72b5aecf",
      "revId": "c160252a40f1ab761bd54169ebad363f61a9ed52",
      "serverId": "3ce6091f-6c88-37e8-8c75-72f92ae8dfba",
      "unresolved": false
    }
  ]
}